2024-12-16 14:28:30,963 -  nornir.core -     INFO -        run() - Running task 'fetch_hostname' with args {} on 1 hosts
2024-12-16 14:28:32,294 - nornir.core.task -    ERROR -      start() - Host 'nan': task 'fetch_hostname' failed with traceback:
Traceback (most recent call last):
  File "/Users/linc/Desktop/Pycharm/operation_platform/.venv/lib/python3.12/site-packages/django/db/backends/utils.py", line 105, in _execute
    return self.cursor.execute(sql, params)
           ^^^^^^^^^^^^^^^^^^^^^^^^^^^^^^^^
  File "/Users/linc/Desktop/Pycharm/operation_platform/.venv/lib/python3.12/site-packages/django/db/backends/sqlite3/base.py", line 354, in execute
    return super().execute(query, params)
           ^^^^^^^^^^^^^^^^^^^^^^^^^^^^^^
sqlite3.IntegrityError: UNIQUE constraint failed: network_cmdb_device.ip

The above exception was the direct cause of the following exception:

Traceback (most recent call last):
  File "/Users/linc/Desktop/Pycharm/operation_platform/.venv/lib/python3.12/site-packages/nornir/core/task.py", line 99, in start
    r = self.task(self, **self.params)
        ^^^^^^^^^^^^^^^^^^^^^^^^^^^^^^
  File "/Users/linc/Desktop/Pycharm/operation_platform/tools/tasks/fetch_hostname.py", line 26, in fetch_hostname
    dev_hostanme.save()
  File "/Users/linc/Desktop/Pycharm/operation_platform/.venv/lib/python3.12/site-packages/django/db/models/base.py", line 891, in save
    self.save_base(
  File "/Users/linc/Desktop/Pycharm/operation_platform/.venv/lib/python3.12/site-packages/django/db/models/base.py", line 997, in save_base
    updated = self._save_table(
              ^^^^^^^^^^^^^^^^^
  File "/Users/linc/Desktop/Pycharm/operation_platform/.venv/lib/python3.12/site-packages/django/db/models/base.py", line 1160, in _save_table
    results = self._do_insert(
              ^^^^^^^^^^^^^^^^
  File "/Users/linc/Desktop/Pycharm/operation_platform/.venv/lib/python3.12/site-packages/django/db/models/base.py", line 1201, in _do_insert
    return manager._insert(
           ^^^^^^^^^^^^^^^^
  File "/Users/linc/Desktop/Pycharm/operation_platform/.venv/lib/python3.12/site-packages/django/db/models/manager.py", line 87, in manager_method
    return getattr(self.get_queryset(), name)(*args, **kwargs)
           ^^^^^^^^^^^^^^^^^^^^^^^^^^^^^^^^^^^^^^^^^^^^^^^^^^^
  File "/Users/linc/Desktop/Pycharm/operation_platform/.venv/lib/python3.12/site-packages/django/db/models/query.py", line 1847, in _insert
    return query.get_compiler(using=using).execute_sql(returning_fields)
           ^^^^^^^^^^^^^^^^^^^^^^^^^^^^^^^^^^^^^^^^^^^^^^^^^^^^^^^^^^^^^
  File "/Users/linc/Desktop/Pycharm/operation_platform/.venv/lib/python3.12/site-packages/django/db/models/sql/compiler.py", line 1836, in execute_sql
    cursor.execute(sql, params)
  File "/Users/linc/Desktop/Pycharm/operation_platform/.venv/lib/python3.12/site-packages/django/db/backends/utils.py", line 122, in execute
    return super().execute(sql, params)
           ^^^^^^^^^^^^^^^^^^^^^^^^^^^^
  File "/Users/linc/Desktop/Pycharm/operation_platform/.venv/lib/python3.12/site-packages/django/db/backends/utils.py", line 79, in execute
    return self._execute_with_wrappers(
           ^^^^^^^^^^^^^^^^^^^^^^^^^^^^
  File "/Users/linc/Desktop/Pycharm/operation_platform/.venv/lib/python3.12/site-packages/django/db/backends/utils.py", line 92, in _execute_with_wrappers
    return executor(sql, params, many, context)
           ^^^^^^^^^^^^^^^^^^^^^^^^^^^^^^^^^^^^
  File "/Users/linc/Desktop/Pycharm/operation_platform/.venv/lib/python3.12/site-packages/django/db/backends/utils.py", line 100, in _execute
    with self.db.wrap_database_errors:
  File "/Users/linc/Desktop/Pycharm/operation_platform/.venv/lib/python3.12/site-packages/django/db/utils.py", line 91, in __exit__
    raise dj_exc_value.with_traceback(traceback) from exc_value
  File "/Users/linc/Desktop/Pycharm/operation_platform/.venv/lib/python3.12/site-packages/django/db/backends/utils.py", line 105, in _execute
    return self.cursor.execute(sql, params)
           ^^^^^^^^^^^^^^^^^^^^^^^^^^^^^^^^
  File "/Users/linc/Desktop/Pycharm/operation_platform/.venv/lib/python3.12/site-packages/django/db/backends/sqlite3/base.py", line 354, in execute
    return super().execute(query, params)
           ^^^^^^^^^^^^^^^^^^^^^^^^^^^^^^
django.db.utils.IntegrityError: UNIQUE constraint failed: network_cmdb_device.ip

2024-12-16 14:32:10,004 -  nornir.core -     INFO -        run() - Running task 'fetch_hostname' with args {} on 1 hosts
2024-12-16 14:32:22,479 -  nornir.core -     INFO -        run() - Running task 'fetch_hostname' with args {} on 1 hosts
2024-12-16 14:47:12,482 -  nornir.core -     INFO -        run() - Running task 'fetch_hostname' with args {} on 1 hosts
2024-12-16 14:47:39,655 -  nornir.core -     INFO -        run() - Running task 'fetch_hostname' with args {} on 2 hosts
2024-12-16 14:47:58,558 -  nornir.core -     INFO -        run() - Running task 'fetch_hostname' with args {} on 1 hosts
2024-12-16 14:48:07,552 -  nornir.core -     INFO -        run() - Running task 'fetch_hostname' with args {} on 2 hosts
2024-12-16 14:48:08,702 -  nornir.core -     INFO -        run() - Running task 'fetch_hostname' with args {} on 2 hosts
2024-12-16 14:48:10,850 - nornir.core.task -    ERROR -      start() - Host 'new_name11': task 'fetch_hostname' failed with traceback:
Traceback (most recent call last):
  File "/Users/linc/Desktop/Pycharm/operation_platform/.venv/lib/python3.12/site-packages/nornir/core/task.py", line 99, in start
    r = self.task(self, **self.params)
        ^^^^^^^^^^^^^^^^^^^^^^^^^^^^^^
  File "/Users/linc/Desktop/Pycharm/operation_platform/tools/tasks/fetch_hostname.py", line 19, in fetch_hostname
    dev = Device.objects.filter(name=task_context.host.name)[0]
          ~~~~~~~~~~~~~~~~~~~~~~~~~~~~~~~~~~~~~~~~~~~~~~~~~~^^^
  File "/Users/linc/Desktop/Pycharm/operation_platform/.venv/lib/python3.12/site-packages/django/db/models/query.py", line 452, in __getitem__
    return qs._result_cache[0]
           ~~~~~~~~~~~~~~~~^^^
IndexError: list index out of range

2024-12-16 14:53:31,638 -  nornir.core -     INFO -        run() - Running task 'fetch_hostname' with args {} on 1 hosts
2024-12-16 14:56:41,367 -  nornir.core -     INFO -        run() - Running task 'fetch_hostname' with args {} on 1 hosts
2024-12-16 14:56:42,716 - nornir.core.task -    ERROR -      start() - Host 'new_name12': task 'fetch_hostname' failed with traceback:
Traceback (most recent call last):
  File "/Users/linc/Desktop/Pycharm/operation_platform/.venv/lib/python3.12/site-packages/nornir/core/task.py", line 99, in start
    r = self.task(self, **self.params)
        ^^^^^^^^^^^^^^^^^^^^^^^^^^^^^^
  File "/Users/linc/Desktop/Pycharm/operation_platform/tools/tasks/fetch_hostname.py", line 12, in fetch_hostname
    print(net_conn.value)
          ^^^^^^^^^^^^^^
AttributeError: 'CiscoIosSSH' object has no attribute 'value'

2024-12-16 14:56:51,928 -  nornir.core -     INFO -        run() - Running task 'fetch_hostname' with args {} on 1 hosts
2024-12-16 14:56:53,325 - nornir.core.task -    ERROR -      start() - Host 'new_name12': task 'fetch_hostname' failed with traceback:
Traceback (most recent call last):
  File "/Users/linc/Desktop/Pycharm/operation_platform/.venv/lib/python3.12/site-packages/nornir/core/task.py", line 99, in start
    r = self.task(self, **self.params)
        ^^^^^^^^^^^^^^^^^^^^^^^^^^^^^^
  File "/Users/linc/Desktop/Pycharm/operation_platform/tools/tasks/fetch_hostname.py", line 12, in fetch_hostname
    print(net_conn.value)
          ^^^^^^^^^^^^^^
AttributeError: 'CiscoIosSSH' object has no attribute 'value'

2024-12-16 14:57:06,046 -  nornir.core -     INFO -        run() - Running task 'fetch_hostname' with args {} on 1 hosts
2024-12-16 14:57:32,998 -  nornir.core -     INFO -        run() - Running task 'fetch_hostname' with args {} on 1 hosts
2024-12-16 14:58:07,683 -  nornir.core -     INFO -        run() - Running task 'fetch_hostname' with args {} on 1 hosts
2024-12-16 14:58:08,863 - nornir.core.task -    ERROR -      start() - Host 'new_name12': task 'fetch_hostname' failed with traceback:
Traceback (most recent call last):
  File "/Users/linc/Desktop/Pycharm/operation_platform/.venv/lib/python3.12/site-packages/nornir/core/task.py", line 99, in start
    r = self.task(self, **self.params)
        ^^^^^^^^^^^^^^^^^^^^^^^^^^^^^^
  File "/Users/linc/Desktop/Pycharm/operation_platform/tools/tasks/fetch_hostname.py", line 12, in fetch_hostname
    print(task_context.host.get_connection())
          ^^^^^^^^^^^^^^^^^^^^^^^^^^^^^^^^^^
TypeError: Host.get_connection() missing 2 required positional arguments: 'connection' and 'configuration'

2024-12-16 14:59:30,094 -  nornir.core -     INFO -        run() - Running task 'fetch_hostname' with args {} on 1 hosts
2024-12-16 14:59:58,735 -  nornir.core -     INFO -        run() - Running task 'fetch_hostname' with args {} on 1 hosts
2024-12-16 15:00:00,155 - nornir.core.task -    ERROR -      start() - Host 'new_name12': task 'fetch_hostname' failed with traceback:
Traceback (most recent call last):
  File "/Users/linc/Desktop/Pycharm/operation_platform/.venv/lib/python3.12/site-packages/nornir/core/task.py", line 99, in start
    r = self.task(self, **self.params)
        ^^^^^^^^^^^^^^^^^^^^^^^^^^^^^^
  File "/Users/linc/Desktop/Pycharm/operation_platform/tools/tasks/fetch_hostname.py", line 12, in fetch_hostname
    print(net_conn.find_pormpt)
          ^^^^^^^^^^^^^^^^^^^^
AttributeError: 'CiscoIosSSH' object has no attribute 'find_pormpt'. Did you mean: 'find_prompt'?

2024-12-16 15:05:05,212 -  nornir.core -     INFO -        run() - Running task 'fetch_hostname' with args {} on 1 hosts
2024-12-16 15:06:30,464 -  nornir.core -     INFO -        run() - Running task 'fetch_hostname' with args {} on 1 hosts
2024-12-16 15:07:32,724 -  nornir.core -     INFO -        run() - Running task 'fetch_hostname' with args {} on 1 hosts
2024-12-16 15:07:52,719 -  nornir.core -     INFO -        run() - Running task 'fetch_hostname' with args {} on 1 hosts
2024-12-16 15:08:12,572 -  nornir.core -     INFO -        run() - Running task 'fetch_hostname' with args {} on 2 hosts
2024-12-16 15:08:50,601 -  nornir.core -     INFO -        run() - Running task 'fetch_hostname' with args {} on 1 hosts
2024-12-16 15:10:13,188 -  nornir.core -     INFO -        run() - Running task 'fetch_hostname' with args {} on 1 hosts
2024-12-16 15:15:03,371 -  nornir.core -     INFO -        run() - Running task 'fetch_hostname' with args {} on 2 hosts
2024-12-16 15:15:37,582 -  nornir.core -     INFO -        run() - Running task 'fetch_hostname' with args {} on 1 hosts
2024-12-16 15:16:47,355 -  nornir.core -     INFO -        run() - Running task 'fetch_hostname' with args {} on 1 hosts
2024-12-16 15:41:53,129 -  nornir.core -     INFO -        run() - Running task 'fetch_hostname' with args {} on 2 hosts
2024-12-16 15:42:07,432 -  nornir.core -     INFO -        run() - Running task 'fetch_hostname' with args {} on 2 hosts
2024-12-16 15:42:32,698 -  nornir.core -     INFO -        run() - Running task 'fetch_hostname' with args {} on 2 hosts
2024-12-16 15:44:33,932 -  nornir.core -     INFO -        run() - Running task 'fetch_hostname' with args {} on 2 hosts
2024-12-16 15:45:30,822 -  nornir.core -     INFO -        run() - Running task 'fetch_hostname' with args {} on 1 hosts
2024-12-16 15:45:33,107 - nornir.core.task -    ERROR -      start() - Host '172.16.180.254': task 'fetch_hostname' failed with traceback:
Traceback (most recent call last):
  File "/Users/linc/Desktop/Pycharm/operation_platform/.venv/lib/python3.12/site-packages/nornir/core/task.py", line 99, in start
    r = self.task(self, **self.params)
        ^^^^^^^^^^^^^^^^^^^^^^^^^^^^^^
  File "/Users/linc/Desktop/Pycharm/operation_platform/tools/tasks/fetch_hostname.py", line 25, in fetch_hostname
    net_conn.close()
    ^^^^^^^^^^^^^^
AttributeError: 'CiscoIosSSH' object has no attribute 'close'

2024-12-16 15:46:25,520 -  nornir.core -     INFO -        run() - Running task 'fetch_hostname' with args {} on 1 hosts
2024-12-16 15:46:27,810 - nornir.core.task -    ERROR -      start() - Host 'DW_LAB_TOR11': task 'fetch_hostname' failed with traceback:
Traceback (most recent call last):
  File "/Users/linc/Desktop/Pycharm/operation_platform/.venv/lib/python3.12/site-packages/nornir/core/task.py", line 99, in start
    r = self.task(self, **self.params)
        ^^^^^^^^^^^^^^^^^^^^^^^^^^^^^^
  File "/Users/linc/Desktop/Pycharm/operation_platform/tools/tasks/fetch_hostname.py", line 25, in fetch_hostname
    net_conn.close()
    ^^^^^^^^^^^^^^
AttributeError: 'CiscoIosSSH' object has no attribute 'close'

2024-12-16 15:48:05,980 -  nornir.core -     INFO -        run() - Running task 'fetch_hostname' with args {} on 1 hosts
2024-12-16 15:48:08,348 - nornir.core.task -    ERROR -      start() - Host 'DW_LAB_TOR': task 'fetch_hostname' failed with traceback:
Traceback (most recent call last):
  File "/Users/linc/Desktop/Pycharm/operation_platform/.venv/lib/python3.12/site-packages/nornir/core/task.py", line 99, in start
    r = self.task(self, **self.params)
        ^^^^^^^^^^^^^^^^^^^^^^^^^^^^^^
  File "/Users/linc/Desktop/Pycharm/operation_platform/tools/tasks/fetch_hostname.py", line 25, in fetch_hostname
    task_context.nornir.close(net_conn)
    ^^^^^^^^^^^^^^^^^^^^^^^^^
AttributeError: 'Nornir' object has no attribute 'close'

2024-12-16 15:48:41,854 -  nornir.core -     INFO -        run() - Running task 'fetch_hostname' with args {} on 1 hosts
2024-12-16 15:48:43,879 - nornir.core.task -    ERROR -      start() - Host 'DW_LAB_TOR': task 'fetch_hostname' failed with traceback:
Traceback (most recent call last):
  File "/Users/linc/Desktop/Pycharm/operation_platform/.venv/lib/python3.12/site-packages/nornir/core/task.py", line 99, in start
    r = self.task(self, **self.params)
        ^^^^^^^^^^^^^^^^^^^^^^^^^^^^^^
  File "/Users/linc/Desktop/Pycharm/operation_platform/tools/tasks/fetch_hostname.py", line 25, in fetch_hostname
    task_context.nornir.close_connection('netmiko', task_context.nornir.config)
    ^^^^^^^^^^^^^^^^^^^^^^^^^^^^^^^^^^^^
AttributeError: 'Nornir' object has no attribute 'close_connection'. Did you mean: 'close_connections'?

2024-12-16 15:48:53,288 -  nornir.core -     INFO -        run() - Running task 'fetch_hostname' with args {} on 1 hosts
2024-12-16 15:48:55,386 - nornir.core.task -    ERROR -      start() - Host 'DW_LAB_TOR': task 'fetch_hostname' failed with traceback:
Traceback (most recent call last):
  File "/Users/linc/Desktop/Pycharm/operation_platform/.venv/lib/python3.12/site-packages/nornir/core/task.py", line 99, in start
    r = self.task(self, **self.params)
        ^^^^^^^^^^^^^^^^^^^^^^^^^^^^^^
  File "/Users/linc/Desktop/Pycharm/operation_platform/tools/tasks/fetch_hostname.py", line 25, in fetch_hostname
    task_context.nornir.close_connection('netmiko', task_context.nornir.config)
    ^^^^^^^^^^^^^^^^^^^^^^^^^^^^^^^^^^^^
AttributeError: 'Nornir' object has no attribute 'close_connection'. Did you mean: 'close_connections'?

2024-12-16 15:49:07,894 -  nornir.core -     INFO -        run() - Running task 'fetch_hostname' with args {} on 1 hosts
2024-12-16 15:49:10,028 - nornir.core.task -    ERROR -      start() - Host 'DW_LAB_TOR': task 'fetch_hostname' failed with traceback:
Traceback (most recent call last):
  File "/Users/linc/Desktop/Pycharm/operation_platform/.venv/lib/python3.12/site-packages/nornir/core/task.py", line 99, in start
    r = self.task(self, **self.params)
        ^^^^^^^^^^^^^^^^^^^^^^^^^^^^^^
  File "/Users/linc/Desktop/Pycharm/operation_platform/tools/tasks/fetch_hostname.py", line 25, in fetch_hostname
    task_context.nornir.close_connection('netmiko', task_context.nornir.config)
    ^^^^^^^^^^^^^^^^^^^^^^^^^^^^^^^^^^^^
AttributeError: 'Nornir' object has no attribute 'close_connection'. Did you mean: 'close_connections'?

2024-12-16 15:49:22,643 -  nornir.core -     INFO -        run() - Running task 'fetch_hostname' with args {} on 1 hosts
2024-12-16 15:49:24,911 - nornir.core.task -    ERROR -      start() - Host 'DW_LAB_TOR': task 'fetch_hostname' failed with traceback:
Traceback (most recent call last):
  File "/Users/linc/Desktop/Pycharm/operation_platform/.venv/lib/python3.12/site-packages/nornir/core/task.py", line 99, in start
    r = self.task(self, **self.params)
        ^^^^^^^^^^^^^^^^^^^^^^^^^^^^^^
  File "/Users/linc/Desktop/Pycharm/operation_platform/tools/tasks/fetch_hostname.py", line 25, in fetch_hostname
    task_context.nornir.close_connection('netmiko')
    ^^^^^^^^^^^^^^^^^^^^^^^^^^^^^^^^^^^^
AttributeError: 'Nornir' object has no attribute 'close_connection'. Did you mean: 'close_connections'?

2024-12-16 15:49:30,140 -  nornir.core -     INFO -        run() - Running task 'fetch_hostname' with args {} on 1 hosts
2024-12-16 15:49:32,201 - nornir.core.task -    ERROR -      start() - Host 'DW_LAB_TOR': task 'fetch_hostname' failed with traceback:
Traceback (most recent call last):
  File "/Users/linc/Desktop/Pycharm/operation_platform/.venv/lib/python3.12/site-packages/nornir/core/task.py", line 99, in start
    r = self.task(self, **self.params)
        ^^^^^^^^^^^^^^^^^^^^^^^^^^^^^^
  File "/Users/linc/Desktop/Pycharm/operation_platform/tools/tasks/fetch_hostname.py", line 25, in fetch_hostname
    task_context.nornir.close_connection('netmiko')
    ^^^^^^^^^^^^^^^^^^^^^^^^^^^^^^^^^^^^
AttributeError: 'Nornir' object has no attribute 'close_connection'. Did you mean: 'close_connections'?

2024-12-16 15:49:54,399 -  nornir.core -     INFO -        run() - Running task 'fetch_hostname' with args {} on 1 hosts
2024-12-16 15:49:56,408 -  nornir.core -     INFO -        run() - Running task 'close_connections_task' with args {} on 1 hosts
2024-12-16 15:50:02,470 -  nornir.core -     INFO -        run() - Running task 'fetch_hostname' with args {} on 1 hosts
2024-12-16 15:50:04,526 -  nornir.core -     INFO -        run() - Running task 'close_connections_task' with args {} on 1 hosts
2024-12-16 16:22:08,345 -  nornir.core -     INFO -        run() - Running task 'fetch_operation' with args {} on 1 hosts
2024-12-16 16:22:14,542 -  nornir.core -     INFO -        run() - Running task 'fetch_operation' with args {} on 1 hosts
2024-12-16 16:22:33,421 -  nornir.core -     INFO -        run() - Running task 'fetch_operation' with args {} on 1 hosts
2024-12-16 16:22:34,627 - nornir.core.task -    ERROR -      start() - Host 'DW_LAB_TOR': task 'fetch_operation' failed with traceback:
Traceback (most recent call last):
  File "/Users/linc/Desktop/Pycharm/operation_platform/.venv/lib/python3.12/site-packages/nornir/core/task.py", line 99, in start
    r = self.task(self, **self.params)
        ^^^^^^^^^^^^^^^^^^^^^^^^^^^^^^
  File "/Users/linc/Desktop/Pycharm/operation_platform/tools/tasks/fetch_operation.py", line 23, in fetch_operation
    enable_pass = net_conn.enable_pass
                  ^^^^^^^^^^^^^^^^^^^^
AttributeError: 'CiscoIosSSH' object has no attribute 'enable_pass'

2024-12-16 16:22:38,355 - nornir.core.task -    ERROR -      start() - Host '172.16.180.143': task 'fetch_operation' failed with traceback:
Traceback (most recent call last):
  File "/Users/linc/Desktop/Pycharm/operation_platform/.venv/lib/python3.12/site-packages/netmiko/base_connection.py", line 1142, in establish_connection
    self.remote_conn_pre.connect(**ssh_connect_params)
  File "/Users/linc/Desktop/Pycharm/operation_platform/.venv/lib/python3.12/site-packages/paramiko/client.py", line 386, in connect
    sock.connect(addr)
TimeoutError: timed out

During handling of the above exception, another exception occurred:

Traceback (most recent call last):
  File "/Users/linc/Desktop/Pycharm/operation_platform/.venv/lib/python3.12/site-packages/nornir/core/task.py", line 99, in start
    r = self.task(self, **self.params)
        ^^^^^^^^^^^^^^^^^^^^^^^^^^^^^^
  File "/Users/linc/Desktop/Pycharm/operation_platform/tools/tasks/fetch_operation.py", line 21, in fetch_operation
    net_conn = task_context.host.get_connection('netmiko', task_context.nornir.config)
               ^^^^^^^^^^^^^^^^^^^^^^^^^^^^^^^^^^^^^^^^^^^^^^^^^^^^^^^^^^^^^^^^^^^^^^^
  File "/Users/linc/Desktop/Pycharm/operation_platform/.venv/lib/python3.12/site-packages/nornir/core/inventory.py", line 494, in get_connection
    self.open_connection(
  File "/Users/linc/Desktop/Pycharm/operation_platform/.venv/lib/python3.12/site-packages/nornir/core/inventory.py", line 546, in open_connection
    conn_obj.open(
  File "/Users/linc/Desktop/Pycharm/operation_platform/.venv/lib/python3.12/site-packages/nornir_netmiko/connections/netmiko.py", line 59, in open
    connection = ConnectHandler(**parameters)
                 ^^^^^^^^^^^^^^^^^^^^^^^^^^^^
  File "/Users/linc/Desktop/Pycharm/operation_platform/.venv/lib/python3.12/site-packages/netmiko/ssh_dispatcher.py", line 410, in ConnectHandler
    return ConnectionClass(*args, **kwargs)
           ^^^^^^^^^^^^^^^^^^^^^^^^^^^^^^^^
  File "/Users/linc/Desktop/Pycharm/operation_platform/.venv/lib/python3.12/site-packages/netmiko/base_connection.py", line 493, in __init__
    self._open()
  File "/Users/linc/Desktop/Pycharm/operation_platform/.venv/lib/python3.12/site-packages/netmiko/base_connection.py", line 498, in _open
    self.establish_connection()
  File "/Users/linc/Desktop/Pycharm/operation_platform/.venv/lib/python3.12/site-packages/netmiko/base_connection.py", line 1164, in establish_connection
    raise NetmikoTimeoutException(msg)
netmiko.exceptions.NetmikoTimeoutException: TCP connection to device failed.

Common causes of this problem are:
1. Incorrect hostname or IP address.
2. Wrong TCP port.
3. Intermediate firewall blocking access.

Device settings: cisco_ios 172.16.180.143:22



2024-12-16 16:22:44,547 - nornir.core.task -    ERROR -      start() - Host '172.16.180.143': task 'fetch_operation' failed with traceback:
Traceback (most recent call last):
  File "/Users/linc/Desktop/Pycharm/operation_platform/.venv/lib/python3.12/site-packages/netmiko/base_connection.py", line 1142, in establish_connection
    self.remote_conn_pre.connect(**ssh_connect_params)
  File "/Users/linc/Desktop/Pycharm/operation_platform/.venv/lib/python3.12/site-packages/paramiko/client.py", line 386, in connect
    sock.connect(addr)
TimeoutError: timed out

During handling of the above exception, another exception occurred:

Traceback (most recent call last):
  File "/Users/linc/Desktop/Pycharm/operation_platform/.venv/lib/python3.12/site-packages/nornir/core/task.py", line 99, in start
    r = self.task(self, **self.params)
        ^^^^^^^^^^^^^^^^^^^^^^^^^^^^^^
  File "/Users/linc/Desktop/Pycharm/operation_platform/tools/tasks/fetch_operation.py", line 21, in fetch_operation
    net_conn = task_context.host.get_connection('netmiko', task_context.nornir.config)
               ^^^^^^^^^^^^^^^^^^^^^^^^^^^^^^^^^^^^^^^^^^^^^^^^^^^^^^^^^^^^^^^^^^^^^^^
  File "/Users/linc/Desktop/Pycharm/operation_platform/.venv/lib/python3.12/site-packages/nornir/core/inventory.py", line 494, in get_connection
    self.open_connection(
  File "/Users/linc/Desktop/Pycharm/operation_platform/.venv/lib/python3.12/site-packages/nornir/core/inventory.py", line 546, in open_connection
    conn_obj.open(
  File "/Users/linc/Desktop/Pycharm/operation_platform/.venv/lib/python3.12/site-packages/nornir_netmiko/connections/netmiko.py", line 59, in open
    connection = ConnectHandler(**parameters)
                 ^^^^^^^^^^^^^^^^^^^^^^^^^^^^
  File "/Users/linc/Desktop/Pycharm/operation_platform/.venv/lib/python3.12/site-packages/netmiko/ssh_dispatcher.py", line 410, in ConnectHandler
    return ConnectionClass(*args, **kwargs)
           ^^^^^^^^^^^^^^^^^^^^^^^^^^^^^^^^
  File "/Users/linc/Desktop/Pycharm/operation_platform/.venv/lib/python3.12/site-packages/netmiko/base_connection.py", line 493, in __init__
    self._open()
  File "/Users/linc/Desktop/Pycharm/operation_platform/.venv/lib/python3.12/site-packages/netmiko/base_connection.py", line 498, in _open
    self.establish_connection()
  File "/Users/linc/Desktop/Pycharm/operation_platform/.venv/lib/python3.12/site-packages/netmiko/base_connection.py", line 1164, in establish_connection
    raise NetmikoTimeoutException(msg)
netmiko.exceptions.NetmikoTimeoutException: TCP connection to device failed.

Common causes of this problem are:
1. Incorrect hostname or IP address.
2. Wrong TCP port.
3. Intermediate firewall blocking access.

Device settings: cisco_ios 172.16.180.143:22



2024-12-16 16:48:48,417 -  nornir.core -     INFO -        run() - Running task 'fetch_operation' with args {} on 2 hosts
2024-12-16 16:48:50,665 - nornir.core.task -    ERROR -      start() - Host 'DW_LAB_TOR': task 'fetch_operation' failed with traceback:
Traceback (most recent call last):
  File "/Users/linc/Desktop/Pycharm/operation_platform/.venv/lib/python3.12/site-packages/nornir/core/task.py", line 99, in start
    r = self.task(self, **self.params)
        ^^^^^^^^^^^^^^^^^^^^^^^^^^^^^^
  File "/Users/linc/Desktop/Pycharm/operation_platform/tools/tasks/fetch_operation.py", line 40, in fetch_operation
    raise Exception
Exception

2024-12-16 16:48:59,652 -  nornir.core -     INFO -        run() - Running task 'fetch_operation' with args {} on 1 hosts
2024-12-16 16:49:02,392 - nornir.core.task -    ERROR -      start() - Host 'DW_LAB_TOR': task 'fetch_operation' failed with traceback:
Traceback (most recent call last):
  File "/Users/linc/Desktop/Pycharm/operation_platform/.venv/lib/python3.12/site-packages/nornir/core/task.py", line 99, in start
    r = self.task(self, **self.params)
        ^^^^^^^^^^^^^^^^^^^^^^^^^^^^^^
  File "/Users/linc/Desktop/Pycharm/operation_platform/tools/tasks/fetch_operation.py", line 40, in fetch_operation
    raise Exception
Exception

2024-12-16 16:49:18,426 - nornir.core.task -    ERROR -      start() - Host '172.16.180.143': task 'fetch_operation' failed with traceback:
Traceback (most recent call last):
  File "/Users/linc/Desktop/Pycharm/operation_platform/.venv/lib/python3.12/site-packages/netmiko/base_connection.py", line 1142, in establish_connection
    self.remote_conn_pre.connect(**ssh_connect_params)
  File "/Users/linc/Desktop/Pycharm/operation_platform/.venv/lib/python3.12/site-packages/paramiko/client.py", line 386, in connect
    sock.connect(addr)
TimeoutError: timed out

During handling of the above exception, another exception occurred:

Traceback (most recent call last):
  File "/Users/linc/Desktop/Pycharm/operation_platform/.venv/lib/python3.12/site-packages/nornir/core/task.py", line 99, in start
    r = self.task(self, **self.params)
        ^^^^^^^^^^^^^^^^^^^^^^^^^^^^^^
  File "/Users/linc/Desktop/Pycharm/operation_platform/tools/tasks/fetch_operation.py", line 22, in fetch_operation
    net_conn = task_context.host.get_connection('netmiko', task_context.nornir.config)
               ^^^^^^^^^^^^^^^^^^^^^^^^^^^^^^^^^^^^^^^^^^^^^^^^^^^^^^^^^^^^^^^^^^^^^^^
  File "/Users/linc/Desktop/Pycharm/operation_platform/.venv/lib/python3.12/site-packages/nornir/core/inventory.py", line 494, in get_connection
    self.open_connection(
  File "/Users/linc/Desktop/Pycharm/operation_platform/.venv/lib/python3.12/site-packages/nornir/core/inventory.py", line 546, in open_connection
    conn_obj.open(
  File "/Users/linc/Desktop/Pycharm/operation_platform/.venv/lib/python3.12/site-packages/nornir_netmiko/connections/netmiko.py", line 59, in open
    connection = ConnectHandler(**parameters)
                 ^^^^^^^^^^^^^^^^^^^^^^^^^^^^
  File "/Users/linc/Desktop/Pycharm/operation_platform/.venv/lib/python3.12/site-packages/netmiko/ssh_dispatcher.py", line 410, in ConnectHandler
    return ConnectionClass(*args, **kwargs)
           ^^^^^^^^^^^^^^^^^^^^^^^^^^^^^^^^
  File "/Users/linc/Desktop/Pycharm/operation_platform/.venv/lib/python3.12/site-packages/netmiko/base_connection.py", line 493, in __init__
    self._open()
  File "/Users/linc/Desktop/Pycharm/operation_platform/.venv/lib/python3.12/site-packages/netmiko/base_connection.py", line 498, in _open
    self.establish_connection()
  File "/Users/linc/Desktop/Pycharm/operation_platform/.venv/lib/python3.12/site-packages/netmiko/base_connection.py", line 1164, in establish_connection
    raise NetmikoTimeoutException(msg)
netmiko.exceptions.NetmikoTimeoutException: TCP connection to device failed.

Common causes of this problem are:
1. Incorrect hostname or IP address.
2. Wrong TCP port.
3. Intermediate firewall blocking access.

Device settings: cisco_ios 172.16.180.143:22



2024-12-16 16:50:04,311 -  nornir.core -     INFO -        run() - Running task 'fetch_hostname' with args {} on 1 hosts
2024-12-16 16:50:06,338 -  nornir.core -     INFO -        run() - Running task 'close_connections_task' with args {} on 1 hosts
2024-12-16 16:50:09,510 -  nornir.core -     INFO -        run() - Running task 'fetch_operation' with args {} on 1 hosts
2024-12-16 16:50:11,786 - nornir.core.task -    ERROR -      start() - Host 'DW_LAB_TOR': task 'fetch_operation' failed with traceback:
Traceback (most recent call last):
  File "/Users/linc/Desktop/Pycharm/operation_platform/.venv/lib/python3.12/site-packages/nornir/core/task.py", line 99, in start
    r = self.task(self, **self.params)
        ^^^^^^^^^^^^^^^^^^^^^^^^^^^^^^
  File "/Users/linc/Desktop/Pycharm/operation_platform/tools/tasks/fetch_operation.py", line 40, in fetch_operation
    raise Exception
Exception

2024-12-16 16:50:52,812 -  nornir.core -     INFO -        run() - Running task 'fetch_operation' with args {} on 1 hosts
2024-12-16 17:12:48,851 -  nornir.core -     INFO -        run() - Running task 'fetch_operation' with args {} on 1 hosts
2024-12-16 17:14:13,236 -  nornir.core -     INFO -        run() - Running task 'fetch_operation' with args {} on 1 hosts
2024-12-16 17:20:47,649 -  nornir.core -     INFO -        run() - Running task 'fetch_operation' with args {} on 1 hosts
2024-12-16 17:29:27,931 -  nornir.core -     INFO -        run() - Running task 'fetch_operation' with args {} on 1 hosts
2024-12-16 21:00:59,627 -  nornir.core -     INFO -        run() - Running task 'fetch_operation' with args {} on 1 hosts
